{"uuid": "bb9ebfe2-95ce-4175-911d-1b0056cc4555", "children": ["0bc6e350-08da-46b6-b799-1b018781c2fe"], "befores": [{"name": "获取用户token", "status": "broken", "statusDetails": {"message": "requests.exceptions.ConnectionError: HTTPSConnectionPool(host='hapi.6noblexc.comapi', port=443): Max retries exceeded with url: /6nobleapi/qnr/userEvaluationForm/getUserEvaluationFormByParams (Caused by NewConnectionError('<urllib3.connection.HTTPSConnection object at 0x000001CE4915C520>: Failed to establish a new connection: [Errno 11001] getaddrinfo failed'))\n", "trace": "  File \"C:\\Users\\jay52\\AppData\\Local\\Programs\\Python\\Python38\\lib\\site-packages\\pluggy\\_callers.py\", line 39, in _multicall\n    res = hook_impl.function(*args)\n  File \"C:\\Users\\jay52\\AppData\\Local\\Programs\\Python\\Python38\\lib\\site-packages\\_pytest\\fixtures.py\", line 1111, in pytest_fixture_setup\n    result = call_fixture_func(fixturefunc, request, kwargs)\n  File \"C:\\Users\\jay52\\AppData\\Local\\Programs\\Python\\Python38\\lib\\site-packages\\_pytest\\fixtures.py\", line 890, in call_fixture_func\n    fixture_result = fixturefunc(**kwargs)\n  File \"D:\\work\\pythonProject(1)(1)\\pythonProject\\conftest.py\", line 41, in Api_Token\n    res=ak.post(url=url,data=login['data'])\n  File \"C:\\Users\\jay52\\AppData\\Local\\Programs\\Python\\Python38\\lib\\site-packages\\allure_commons\\_allure.py\", line 172, in impl\n    return func(*a, **kw)\n  File \"D:\\work\\pythonProject(1)(1)\\pythonProject\\KeyWords\\Api_Keys.py\", line 13, in post\n    return requests.post(url=url,data=data,**kwargs)\n  File \"C:\\Users\\jay52\\AppData\\Local\\Programs\\Python\\Python38\\lib\\site-packages\\requests\\api.py\", line 115, in post\n    return request(\"post\", url, data=data, json=json, **kwargs)\n  File \"C:\\Users\\jay52\\AppData\\Local\\Programs\\Python\\Python38\\lib\\site-packages\\requests\\api.py\", line 59, in request\n    return session.request(method=method, url=url, **kwargs)\n  File \"C:\\Users\\jay52\\AppData\\Local\\Programs\\Python\\Python38\\lib\\site-packages\\requests\\sessions.py\", line 587, in request\n    resp = self.send(prep, **send_kwargs)\n  File \"C:\\Users\\jay52\\AppData\\Local\\Programs\\Python\\Python38\\lib\\site-packages\\requests\\sessions.py\", line 701, in send\n    r = adapter.send(request, **kwargs)\n  File \"C:\\Users\\jay52\\AppData\\Local\\Programs\\Python\\Python38\\lib\\site-packages\\requests\\adapters.py\", line 565, in send\n    raise ConnectionError(e, request=request)\n"}, "steps": [{"name": "发送登录接口请求，并生成用户的token，整个项目仅生成一次", "status": "broken", "statusDetails": {"message": "requests.exceptions.ConnectionError: HTTPSConnectionPool(host='hapi.6noblexc.comapi', port=443): Max retries exceeded with url: /6nobleapi/qnr/userEvaluationForm/getUserEvaluationFormByParams (Caused by NewConnectionError('<urllib3.connection.HTTPSConnection object at 0x000001CE4915C520>: Failed to establish a new connection: [Errno 11001] getaddrinfo failed'))\n", "trace": "  File \"D:\\work\\pythonProject(1)(1)\\pythonProject\\conftest.py\", line 41, in Api_Token\n    res=ak.post(url=url,data=login['data'])\n  File \"C:\\Users\\jay52\\AppData\\Local\\Programs\\Python\\Python38\\lib\\site-packages\\allure_commons\\_allure.py\", line 172, in impl\n    return func(*a, **kw)\n  File \"D:\\work\\pythonProject(1)(1)\\pythonProject\\KeyWords\\Api_Keys.py\", line 13, in post\n    return requests.post(url=url,data=data,**kwargs)\n  File \"C:\\Users\\jay52\\AppData\\Local\\Programs\\Python\\Python38\\lib\\site-packages\\requests\\api.py\", line 115, in post\n    return request(\"post\", url, data=data, json=json, **kwargs)\n  File \"C:\\Users\\jay52\\AppData\\Local\\Programs\\Python\\Python38\\lib\\site-packages\\requests\\api.py\", line 59, in request\n    return session.request(method=method, url=url, **kwargs)\n  File \"C:\\Users\\jay52\\AppData\\Local\\Programs\\Python\\Python38\\lib\\site-packages\\requests\\sessions.py\", line 587, in request\n    resp = self.send(prep, **send_kwargs)\n  File \"C:\\Users\\jay52\\AppData\\Local\\Programs\\Python\\Python38\\lib\\site-packages\\requests\\sessions.py\", line 701, in send\n    r = adapter.send(request, **kwargs)\n  File \"C:\\Users\\jay52\\AppData\\Local\\Programs\\Python\\Python38\\lib\\site-packages\\requests\\adapters.py\", line 565, in send\n    raise ConnectionError(e, request=request)\n"}, "steps": [{"name": "发送post请求", "status": "broken", "statusDetails": {"message": "requests.exceptions.ConnectionError: HTTPSConnectionPool(host='hapi.6noblexc.comapi', port=443): Max retries exceeded with url: /6nobleapi/qnr/userEvaluationForm/getUserEvaluationFormByParams (Caused by NewConnectionError('<urllib3.connection.HTTPSConnection object at 0x000001CE4915C520>: Failed to establish a new connection: [Errno 11001] getaddrinfo failed'))\n", "trace": "  File \"C:\\Users\\jay52\\AppData\\Local\\Programs\\Python\\Python38\\lib\\site-packages\\allure_commons\\_allure.py\", line 172, in impl\n    return func(*a, **kw)\n  File \"D:\\work\\pythonProject(1)(1)\\pythonProject\\KeyWords\\Api_Keys.py\", line 13, in post\n    return requests.post(url=url,data=data,**kwargs)\n  File \"C:\\Users\\jay52\\AppData\\Local\\Programs\\Python\\Python38\\lib\\site-packages\\requests\\api.py\", line 115, in post\n    return request(\"post\", url, data=data, json=json, **kwargs)\n  File \"C:\\Users\\jay52\\AppData\\Local\\Programs\\Python\\Python38\\lib\\site-packages\\requests\\api.py\", line 59, in request\n    return session.request(method=method, url=url, **kwargs)\n  File \"C:\\Users\\jay52\\AppData\\Local\\Programs\\Python\\Python38\\lib\\site-packages\\requests\\sessions.py\", line 587, in request\n    resp = self.send(prep, **send_kwargs)\n  File \"C:\\Users\\jay52\\AppData\\Local\\Programs\\Python\\Python38\\lib\\site-packages\\requests\\sessions.py\", line 701, in send\n    r = adapter.send(request, **kwargs)\n  File \"C:\\Users\\jay52\\AppData\\Local\\Programs\\Python\\Python38\\lib\\site-packages\\requests\\adapters.py\", line 565, in send\n    raise ConnectionError(e, request=request)\n"}, "parameters": [{"name": "url", "value": "'https://hapi.6noblexc.comapi/6nobleapi/qnr/userEvaluationForm/getUserEvaluationFormByParams'"}, {"name": "data", "value": "{'params': {'params': [0, 2, 1]}, 'publicKey': 'pvj9bTwwaY4YdPiwRBH5RE25o9ZM8BHG', 'token': None}"}], "start": 1656402141739, "stop": 1656402141747}], "start": 1656402141739, "stop": 1656402141763}], "start": 1656402141739, "stop": 1656402141764}], "start": 1656402141739, "stop": 1656402141935}